{"level":"ERROR","location":"[exception:108] fyers_logger","message":"Attempt to send on a closed protocol","timestamp":"2024-07-21 05:54:44,467+0530","service":"FyersDataSocket","exception":"Traceback (most recent call last):\n  File \"/usr/local/lib/python3.8/site-packages/fyers_apiv3/FyersWebsocket/data_ws.py\", line 1434, in On_message\n    self.OnMessage(message)\n  File \"/code/fyersapi/consumers.py\", line 178, in on_message\n    self.send(text_data=f\"{message}\")\n  File \"/usr/local/lib/python3.8/site-packages/channels/generic/websocket.py\", line 74, in send\n    super().send({\"type\": \"websocket.send\", \"text\": text_data})\n  File \"/usr/local/lib/python3.8/site-packages/channels/consumer.py\", line 133, in send\n    self.base_send(message)\n  File \"/usr/local/lib/python3.8/site-packages/asgiref/sync.py\", line 277, in __call__\n    return call_result.result()\n  File \"/usr/local/lib/python3.8/concurrent/futures/_base.py\", line 437, in result\n    return self.__get_result()\n  File \"/usr/local/lib/python3.8/concurrent/futures/_base.py\", line 389, in __get_result\n    raise self._exception\n  File \"/usr/local/lib/python3.8/site-packages/asgiref/sync.py\", line 353, in main_wrap\n    result = await self.awaitable(*args, **kwargs)\n  File \"/usr/local/lib/python3.8/site-packages/channels/sessions.py\", line 226, in send\n    return await self.real_send(message)\n  File \"/usr/local/lib/python3.8/site-packages/daphne/server.py\", line 234, in handle_reply\n    protocol.handle_reply(message)\n  File \"/usr/local/lib/python3.8/site-packages/daphne/ws_protocol.py\", line 202, in handle_reply\n    self.serverSend(message[\"text\"], False)\n  File \"/usr/local/lib/python3.8/site-packages/daphne/ws_protocol.py\", line 256, in serverSend\n    self.sendMessage(content.encode(\"utf8\"), binary)\n  File \"/usr/local/lib/python3.8/site-packages/autobahn/websocket/protocol.py\", line 2275, in sendMessage\n    raise Disconnected(\"Attempt to send on a closed protocol\")\nautobahn.exception.Disconnected: Attempt to send on a closed protocol","exception_name":"Disconnected"}
{"level":"ERROR","location":"[exception:108] fyers_logger","message":"Attempt to send on a closed protocol","timestamp":"2024-07-21 05:54:44,481+0530","service":"FyersDataSocket","exception":"Traceback (most recent call last):\n  File \"/usr/local/lib/python3.8/site-packages/asgiref/sync.py\", line 349, in main_wrap\n    raise exc_info[1]\n  File \"/usr/local/lib/python3.8/site-packages/fyers_apiv3/FyersWebsocket/data_ws.py\", line 1434, in On_message\n    self.OnMessage(message)\n  File \"/code/fyersapi/consumers.py\", line 178, in on_message\n    self.send(text_data=f\"{message}\")\n  File \"/usr/local/lib/python3.8/site-packages/channels/generic/websocket.py\", line 74, in send\n    super().send({\"type\": \"websocket.send\", \"text\": text_data})\n  File \"/usr/local/lib/python3.8/site-packages/channels/consumer.py\", line 133, in send\n    self.base_send(message)\n  File \"/usr/local/lib/python3.8/site-packages/asgiref/sync.py\", line 277, in __call__\n    return call_result.result()\n  File \"/usr/local/lib/python3.8/concurrent/futures/_base.py\", line 437, in result\n    return self.__get_result()\n  File \"/usr/local/lib/python3.8/concurrent/futures/_base.py\", line 389, in __get_result\n    raise self._exception\n  File \"/usr/local/lib/python3.8/site-packages/asgiref/sync.py\", line 353, in main_wrap\n    result = await self.awaitable(*args, **kwargs)\n  File \"/usr/local/lib/python3.8/site-packages/channels/sessions.py\", line 226, in send\n    return await self.real_send(message)\n  File \"/usr/local/lib/python3.8/site-packages/daphne/server.py\", line 234, in handle_reply\n    protocol.handle_reply(message)\n  File \"/usr/local/lib/python3.8/site-packages/daphne/ws_protocol.py\", line 202, in handle_reply\n    self.serverSend(message[\"text\"], False)\n  File \"/usr/local/lib/python3.8/site-packages/daphne/ws_protocol.py\", line 256, in serverSend\n    self.sendMessage(content.encode(\"utf8\"), binary)\n  File \"/usr/local/lib/python3.8/site-packages/autobahn/websocket/protocol.py\", line 2275, in sendMessage\n    raise Disconnected(\"Attempt to send on a closed protocol\")\nautobahn.exception.Disconnected: Attempt to send on a closed protocol\n\nDuring handling of the above exception, another exception occurred:\n\nTraceback (most recent call last):\n  File \"/usr/local/lib/python3.8/site-packages/fyers_apiv3/FyersWebsocket/data_ws.py\", line 745, in __unsubscribe_resp\n    self.On_message(\n  File \"/usr/local/lib/python3.8/site-packages/fyers_apiv3/FyersWebsocket/data_ws.py\", line 1448, in On_message\n    self.On_error(e)\n  File \"/usr/local/lib/python3.8/site-packages/fyers_apiv3/FyersWebsocket/data_ws.py\", line 1501, in On_error\n    self.OnError(message)\n  File \"/code/fyersapi/consumers.py\", line 182, in on_error\n    self.send(text_data=f\"Error: {message}\")\n  File \"/usr/local/lib/python3.8/site-packages/channels/generic/websocket.py\", line 74, in send\n    super().send({\"type\": \"websocket.send\", \"text\": text_data})\n  File \"/usr/local/lib/python3.8/site-packages/channels/consumer.py\", line 133, in send\n    self.base_send(message)\n  File \"/usr/local/lib/python3.8/site-packages/asgiref/sync.py\", line 277, in __call__\n    return call_result.result()\n  File \"/usr/local/lib/python3.8/concurrent/futures/_base.py\", line 437, in result\n    return self.__get_result()\n  File \"/usr/local/lib/python3.8/concurrent/futures/_base.py\", line 389, in __get_result\n    raise self._exception\n  File \"/usr/local/lib/python3.8/site-packages/asgiref/sync.py\", line 351, in main_wrap\n    result = await self.awaitable(*args, **kwargs)\n  File \"/usr/local/lib/python3.8/site-packages/channels/sessions.py\", line 226, in send\n    return await self.real_send(message)\n  File \"/usr/local/lib/python3.8/site-packages/daphne/server.py\", line 234, in handle_reply\n    protocol.handle_reply(message)\n  File \"/usr/local/lib/python3.8/site-packages/daphne/ws_protocol.py\", line 202, in handle_reply\n    self.serverSend(message[\"text\"], False)\n  File \"/usr/local/lib/python3.8/site-packages/daphne/ws_protocol.py\", line 256, in serverSend\n    self.sendMessage(content.encode(\"utf8\"), binary)\n  File \"/usr/local/lib/python3.8/site-packages/autobahn/websocket/protocol.py\", line 2275, in sendMessage\n    raise Disconnected(\"Attempt to send on a closed protocol\")\nautobahn.exception.Disconnected: Attempt to send on a closed protocol","exception_name":"Disconnected"}
{"level":"ERROR","location":"[exception:108] fyers_logger","message":"Attempt to send on a closed protocol","timestamp":"2024-07-21 05:56:34,789+0530","service":"FyersDataSocket","exception":"Traceback (most recent call last):\n  File \"/usr/local/lib/python3.8/site-packages/fyers_apiv3/FyersWebsocket/data_ws.py\", line 1434, in On_message\n    self.OnMessage(message)\n  File \"/code/fyersapi/consumers.py\", line 178, in on_message\n    self.send(text_data=f\"{message}\")\n  File \"/usr/local/lib/python3.8/site-packages/channels/generic/websocket.py\", line 74, in send\n    super().send({\"type\": \"websocket.send\", \"text\": text_data})\n  File \"/usr/local/lib/python3.8/site-packages/channels/consumer.py\", line 133, in send\n    self.base_send(message)\n  File \"/usr/local/lib/python3.8/site-packages/asgiref/sync.py\", line 277, in __call__\n    return call_result.result()\n  File \"/usr/local/lib/python3.8/concurrent/futures/_base.py\", line 437, in result\n    return self.__get_result()\n  File \"/usr/local/lib/python3.8/concurrent/futures/_base.py\", line 389, in __get_result\n    raise self._exception\n  File \"/usr/local/lib/python3.8/site-packages/asgiref/sync.py\", line 353, in main_wrap\n    result = await self.awaitable(*args, **kwargs)\n  File \"/usr/local/lib/python3.8/site-packages/channels/sessions.py\", line 226, in send\n    return await self.real_send(message)\n  File \"/usr/local/lib/python3.8/site-packages/daphne/server.py\", line 234, in handle_reply\n    protocol.handle_reply(message)\n  File \"/usr/local/lib/python3.8/site-packages/daphne/ws_protocol.py\", line 202, in handle_reply\n    self.serverSend(message[\"text\"], False)\n  File \"/usr/local/lib/python3.8/site-packages/daphne/ws_protocol.py\", line 256, in serverSend\n    self.sendMessage(content.encode(\"utf8\"), binary)\n  File \"/usr/local/lib/python3.8/site-packages/autobahn/websocket/protocol.py\", line 2275, in sendMessage\n    raise Disconnected(\"Attempt to send on a closed protocol\")\nautobahn.exception.Disconnected: Attempt to send on a closed protocol","exception_name":"Disconnected"}
{"level":"ERROR","location":"[exception:108] fyers_logger","message":"Attempt to send on a closed protocol","timestamp":"2024-07-21 05:56:34,793+0530","service":"FyersDataSocket","exception":"Traceback (most recent call last):\n  File \"/usr/local/lib/python3.8/site-packages/asgiref/sync.py\", line 349, in main_wrap\n    raise exc_info[1]\n  File \"/usr/local/lib/python3.8/site-packages/fyers_apiv3/FyersWebsocket/data_ws.py\", line 1434, in On_message\n    self.OnMessage(message)\n  File \"/code/fyersapi/consumers.py\", line 178, in on_message\n    self.send(text_data=f\"{message}\")\n  File \"/usr/local/lib/python3.8/site-packages/channels/generic/websocket.py\", line 74, in send\n    super().send({\"type\": \"websocket.send\", \"text\": text_data})\n  File \"/usr/local/lib/python3.8/site-packages/channels/consumer.py\", line 133, in send\n    self.base_send(message)\n  File \"/usr/local/lib/python3.8/site-packages/asgiref/sync.py\", line 277, in __call__\n    return call_result.result()\n  File \"/usr/local/lib/python3.8/concurrent/futures/_base.py\", line 437, in result\n    return self.__get_result()\n  File \"/usr/local/lib/python3.8/concurrent/futures/_base.py\", line 389, in __get_result\n    raise self._exception\n  File \"/usr/local/lib/python3.8/site-packages/asgiref/sync.py\", line 353, in main_wrap\n    result = await self.awaitable(*args, **kwargs)\n  File \"/usr/local/lib/python3.8/site-packages/channels/sessions.py\", line 226, in send\n    return await self.real_send(message)\n  File \"/usr/local/lib/python3.8/site-packages/daphne/server.py\", line 234, in handle_reply\n    protocol.handle_reply(message)\n  File \"/usr/local/lib/python3.8/site-packages/daphne/ws_protocol.py\", line 202, in handle_reply\n    self.serverSend(message[\"text\"], False)\n  File \"/usr/local/lib/python3.8/site-packages/daphne/ws_protocol.py\", line 256, in serverSend\n    self.sendMessage(content.encode(\"utf8\"), binary)\n  File \"/usr/local/lib/python3.8/site-packages/autobahn/websocket/protocol.py\", line 2275, in sendMessage\n    raise Disconnected(\"Attempt to send on a closed protocol\")\nautobahn.exception.Disconnected: Attempt to send on a closed protocol\n\nDuring handling of the above exception, another exception occurred:\n\nTraceback (most recent call last):\n  File \"/usr/local/lib/python3.8/site-packages/fyers_apiv3/FyersWebsocket/data_ws.py\", line 745, in __unsubscribe_resp\n    self.On_message(\n  File \"/usr/local/lib/python3.8/site-packages/fyers_apiv3/FyersWebsocket/data_ws.py\", line 1448, in On_message\n    self.On_error(e)\n  File \"/usr/local/lib/python3.8/site-packages/fyers_apiv3/FyersWebsocket/data_ws.py\", line 1501, in On_error\n    self.OnError(message)\n  File \"/code/fyersapi/consumers.py\", line 182, in on_error\n    self.send(text_data=f\"Error: {message}\")\n  File \"/usr/local/lib/python3.8/site-packages/channels/generic/websocket.py\", line 74, in send\n    super().send({\"type\": \"websocket.send\", \"text\": text_data})\n  File \"/usr/local/lib/python3.8/site-packages/channels/consumer.py\", line 133, in send\n    self.base_send(message)\n  File \"/usr/local/lib/python3.8/site-packages/asgiref/sync.py\", line 277, in __call__\n    return call_result.result()\n  File \"/usr/local/lib/python3.8/concurrent/futures/_base.py\", line 437, in result\n    return self.__get_result()\n  File \"/usr/local/lib/python3.8/concurrent/futures/_base.py\", line 389, in __get_result\n    raise self._exception\n  File \"/usr/local/lib/python3.8/site-packages/asgiref/sync.py\", line 351, in main_wrap\n    result = await self.awaitable(*args, **kwargs)\n  File \"/usr/local/lib/python3.8/site-packages/channels/sessions.py\", line 226, in send\n    return await self.real_send(message)\n  File \"/usr/local/lib/python3.8/site-packages/daphne/server.py\", line 234, in handle_reply\n    protocol.handle_reply(message)\n  File \"/usr/local/lib/python3.8/site-packages/daphne/ws_protocol.py\", line 202, in handle_reply\n    self.serverSend(message[\"text\"], False)\n  File \"/usr/local/lib/python3.8/site-packages/daphne/ws_protocol.py\", line 256, in serverSend\n    self.sendMessage(content.encode(\"utf8\"), binary)\n  File \"/usr/local/lib/python3.8/site-packages/autobahn/websocket/protocol.py\", line 2275, in sendMessage\n    raise Disconnected(\"Attempt to send on a closed protocol\")\nautobahn.exception.Disconnected: Attempt to send on a closed protocol","exception_name":"Disconnected"}
{"level":"ERROR","location":"[exception:108] fyers_logger","message":"Attempt to send on a closed protocol","timestamp":"2024-07-21 05:56:46,635+0530","service":"FyersDataSocket","exception":"Traceback (most recent call last):\n  File \"/usr/local/lib/python3.8/site-packages/fyers_apiv3/FyersWebsocket/data_ws.py\", line 1434, in On_message\n    self.OnMessage(message)\n  File \"/code/fyersapi/consumers.py\", line 178, in on_message\n    self.send(text_data=f\"{message}\")\n  File \"/usr/local/lib/python3.8/site-packages/channels/generic/websocket.py\", line 74, in send\n    super().send({\"type\": \"websocket.send\", \"text\": text_data})\n  File \"/usr/local/lib/python3.8/site-packages/channels/consumer.py\", line 133, in send\n    self.base_send(message)\n  File \"/usr/local/lib/python3.8/site-packages/asgiref/sync.py\", line 277, in __call__\n    return call_result.result()\n  File \"/usr/local/lib/python3.8/concurrent/futures/_base.py\", line 437, in result\n    return self.__get_result()\n  File \"/usr/local/lib/python3.8/concurrent/futures/_base.py\", line 389, in __get_result\n    raise self._exception\n  File \"/usr/local/lib/python3.8/site-packages/asgiref/sync.py\", line 353, in main_wrap\n    result = await self.awaitable(*args, **kwargs)\n  File \"/usr/local/lib/python3.8/site-packages/channels/sessions.py\", line 226, in send\n    return await self.real_send(message)\n  File \"/usr/local/lib/python3.8/site-packages/daphne/server.py\", line 234, in handle_reply\n    protocol.handle_reply(message)\n  File \"/usr/local/lib/python3.8/site-packages/daphne/ws_protocol.py\", line 202, in handle_reply\n    self.serverSend(message[\"text\"], False)\n  File \"/usr/local/lib/python3.8/site-packages/daphne/ws_protocol.py\", line 256, in serverSend\n    self.sendMessage(content.encode(\"utf8\"), binary)\n  File \"/usr/local/lib/python3.8/site-packages/autobahn/websocket/protocol.py\", line 2275, in sendMessage\n    raise Disconnected(\"Attempt to send on a closed protocol\")\nautobahn.exception.Disconnected: Attempt to send on a closed protocol","exception_name":"Disconnected"}
{"level":"ERROR","location":"[exception:108] fyers_logger","message":"Attempt to send on a closed protocol","timestamp":"2024-07-21 05:56:46,638+0530","service":"FyersDataSocket","exception":"Traceback (most recent call last):\n  File \"/usr/local/lib/python3.8/site-packages/asgiref/sync.py\", line 349, in main_wrap\n    raise exc_info[1]\n  File \"/usr/local/lib/python3.8/site-packages/fyers_apiv3/FyersWebsocket/data_ws.py\", line 1434, in On_message\n    self.OnMessage(message)\n  File \"/code/fyersapi/consumers.py\", line 178, in on_message\n    self.send(text_data=f\"{message}\")\n  File \"/usr/local/lib/python3.8/site-packages/channels/generic/websocket.py\", line 74, in send\n    super().send({\"type\": \"websocket.send\", \"text\": text_data})\n  File \"/usr/local/lib/python3.8/site-packages/channels/consumer.py\", line 133, in send\n    self.base_send(message)\n  File \"/usr/local/lib/python3.8/site-packages/asgiref/sync.py\", line 277, in __call__\n    return call_result.result()\n  File \"/usr/local/lib/python3.8/concurrent/futures/_base.py\", line 437, in result\n    return self.__get_result()\n  File \"/usr/local/lib/python3.8/concurrent/futures/_base.py\", line 389, in __get_result\n    raise self._exception\n  File \"/usr/local/lib/python3.8/site-packages/asgiref/sync.py\", line 353, in main_wrap\n    result = await self.awaitable(*args, **kwargs)\n  File \"/usr/local/lib/python3.8/site-packages/channels/sessions.py\", line 226, in send\n    return await self.real_send(message)\n  File \"/usr/local/lib/python3.8/site-packages/daphne/server.py\", line 234, in handle_reply\n    protocol.handle_reply(message)\n  File \"/usr/local/lib/python3.8/site-packages/daphne/ws_protocol.py\", line 202, in handle_reply\n    self.serverSend(message[\"text\"], False)\n  File \"/usr/local/lib/python3.8/site-packages/daphne/ws_protocol.py\", line 256, in serverSend\n    self.sendMessage(content.encode(\"utf8\"), binary)\n  File \"/usr/local/lib/python3.8/site-packages/autobahn/websocket/protocol.py\", line 2275, in sendMessage\n    raise Disconnected(\"Attempt to send on a closed protocol\")\nautobahn.exception.Disconnected: Attempt to send on a closed protocol\n\nDuring handling of the above exception, another exception occurred:\n\nTraceback (most recent call last):\n  File \"/usr/local/lib/python3.8/site-packages/fyers_apiv3/FyersWebsocket/data_ws.py\", line 745, in __unsubscribe_resp\n    self.On_message(\n  File \"/usr/local/lib/python3.8/site-packages/fyers_apiv3/FyersWebsocket/data_ws.py\", line 1448, in On_message\n    self.On_error(e)\n  File \"/usr/local/lib/python3.8/site-packages/fyers_apiv3/FyersWebsocket/data_ws.py\", line 1501, in On_error\n    self.OnError(message)\n  File \"/code/fyersapi/consumers.py\", line 182, in on_error\n    self.send(text_data=f\"Error: {message}\")\n  File \"/usr/local/lib/python3.8/site-packages/channels/generic/websocket.py\", line 74, in send\n    super().send({\"type\": \"websocket.send\", \"text\": text_data})\n  File \"/usr/local/lib/python3.8/site-packages/channels/consumer.py\", line 133, in send\n    self.base_send(message)\n  File \"/usr/local/lib/python3.8/site-packages/asgiref/sync.py\", line 277, in __call__\n    return call_result.result()\n  File \"/usr/local/lib/python3.8/concurrent/futures/_base.py\", line 437, in result\n    return self.__get_result()\n  File \"/usr/local/lib/python3.8/concurrent/futures/_base.py\", line 389, in __get_result\n    raise self._exception\n  File \"/usr/local/lib/python3.8/site-packages/asgiref/sync.py\", line 351, in main_wrap\n    result = await self.awaitable(*args, **kwargs)\n  File \"/usr/local/lib/python3.8/site-packages/channels/sessions.py\", line 226, in send\n    return await self.real_send(message)\n  File \"/usr/local/lib/python3.8/site-packages/daphne/server.py\", line 234, in handle_reply\n    protocol.handle_reply(message)\n  File \"/usr/local/lib/python3.8/site-packages/daphne/ws_protocol.py\", line 202, in handle_reply\n    self.serverSend(message[\"text\"], False)\n  File \"/usr/local/lib/python3.8/site-packages/daphne/ws_protocol.py\", line 256, in serverSend\n    self.sendMessage(content.encode(\"utf8\"), binary)\n  File \"/usr/local/lib/python3.8/site-packages/autobahn/websocket/protocol.py\", line 2275, in sendMessage\n    raise Disconnected(\"Attempt to send on a closed protocol\")\nautobahn.exception.Disconnected: Attempt to send on a closed protocol","exception_name":"Disconnected"}
